Workbook
Name Acumulado_Sugestao: 'Simulador de Investimentos'!$E$79
Name Aporte: 'Simulador de Investimentos'!$E$26
Name Dividendo_Carro: 'Compra do carro'!$E$26
Name Objetivo_Financeiro: 'Compra do carro'!$E$17
Name Patrimonio: 'Simulador de Investimentos'!$E$29
Name Patrimonio_10: 'Simulador de Investimentos'!$D$36
Name Patrimonio_2: 'Simulador de Investimentos'!$D$34
Name Patrimonio_30: 'Simulador de Investimentos'!$D$38
Name Patrimonio_5: 'Simulador de Investimentos'!$D$35
Name Qtd_Anos: 'Simulador de Investimentos'!$E$27
Name Renda_Mensal_10: 'Simulador de Investimentos'!$E$36
Name Renda_Mensal_2: 'Simulador de Investimentos'!$E$34
Name Renda_Mensal_20: 'Simulador de Investimentos'!$E$37
Name Renda_Mensal_5: 'Simulador de Investimentos'!$E$35
Name Rendimento_Carro: 'Compra do carro'!$E$16
Name Salario: 'Simulador de Investimentos'!$E$20
Name Salario_mes: 'Compra do carro'!$E$15
Name Sugestao_Investimento: 'Simulador de Investimentos'!$E$22
Name Taxa_Mensal: 'Simulador de Investimentos'!$E$28
Name Taxa_Nova_Simulacao: 'Simulador de Investimentos'!$E$78
Name Taxa_Rendimento: 'Simulador de Investimentos'!$E$21
Name Taxa_rendimento_Carro: 'Compra do carro'!$E$24
Name Tempo_para_Carro: 'Compra do carro'!$E$23
Name Valor_Acumulado_Carro: 'Compra do carro'!$E$25
Name Valor_para_Carro: 'Compra do carro'!$E$18

Sheet Simulador de Investimentos
C19: Configurações
C20: Salário | E20: 8000
C21: Rendimento Carteira | E21: 0.0089
C22: Sugestão de Investimento (30% ao mês) | E22: =E20*30% -> 2400
C25: INVESTIMENTO MENSAL
C26: Quanto investir por mês? | E26: 500
C27: Por quantos anos? | E27: 5
C28: Taxa de rendimento mensal? | E28: 0.01078
C29: Patrimônio acumulado? | E29: =FV(Taxa_Mensal,Qtd_Anos*12,Aporte*-1) -> 41874.91
C30: Dividendos mensais? | E30: =Patrimonio*Taxa_Mensal -> 451.41153
C33: Cenários | E33: Dividendo
A34: 2 | C34: Quanto em 2 anos? | D34: =FV(Taxa_Mensal,A34*12,Aporte*-1) -> 13612.196 | E34: =D34*Taxa_Mensal -> 146.73947
A35: 5 | C35: Quanto em 5 anos? | D35: =FV(Taxa_Mensal,A35*12,Aporte*-1) -> 41874.91 | E35: =D35*Taxa_Mensal -> 451.41153
A36: 10 | C36: Quanto em 10 anos? | D36: =FV(Taxa_Mensal,A36*12,Aporte*-1) -> 121555.45 | E36: =D36*Taxa_Mensal -> 1310.3678
A37: 20 | C37: Quanto em 20 anos? | D37: =FV(Taxa_Mensal,A37*12,Aporte*-1) -> 561675.61 | E37: =D37*Taxa_Mensal -> 6054.8631
A38: 30 | C38: Quanto em 30 anos? | D38: =FV(Taxa_Mensal,A38*12,Aporte*-1) -> 2155234.3 | E38: =D38*Taxa_Mensal -> 23233.426
C41: Perfil | D41: Conservador
C42: VALOR A SER INVESTIDO POR MÊS | D42: =Aporte -> 500
C45: TIPO DE FII | D45: Percentual Sugerido | E45: Valores
C46: PAPEL | D46: =VLOOKUP($D$41&"-"&C46,Apoio!$B:$E,4,FALSE) -> 0.3 | E46: =D46*$D$42 -> 150
C47: TIJOLO | D47: =VLOOKUP($D$41&"-"&C47,Apoio!$B:$E,4,FALSE) -> 0.5 | E47: =D47*$D$42 -> 250
C48: HIBRIDOS | D48: =VLOOKUP($D$41&"-"&C48,Apoio!$B:$E,4,FALSE) -> 0.1 | E48: =D48*$D$42 -> 50
C49: FOFS | D49: =VLOOKUP($D$41&"-"&C49,Apoio!$B:$E,4,FALSE) -> 0.05 | E49: =D49*$D$42 -> 25
C50: DESENVOLVIMENTO | D50: =VLOOKUP($D$41&"-"&C50,Apoio!$B:$E,4,FALSE) -> 0.05 | E50: =D50*$D$42 -> 25
C51: HOTELARIAS | D51: =VLOOKUP($D$41&"-"&C51,Apoio!$B:$E,4,FALSE) -> 0 | E51: =D51*$D$42 -> 0
E52: =SUM(E46:E51) -> 500
C75: Sugestão em 30% da renda
C76: Quanto investir por mês? | E76: =Sugestao_Investimento -> 2400
C77: Por quantos anos? | E77: 5
C78: Taxa de rendimento mensal? | E78: 0.01078
C79: Patrimônio acumulado? | E79: =FV(Taxa_Nova_Simulacao,E77*12,E76*-1) -> 200999.57
C80: Dividendos mensais? | E80: =Acumulado_Sugestao*Taxa_Nova_Simulacao -> 2166.7753
C84: Cenários | E84: Dividendo
A85: 2 | C85: Quanto em 2 anos? | D85: =FV(Taxa_Nova_Simulacao,A85*12,Sugestao_Investimento*-1) -> 65338.539 | E85: =D85*Taxa_Nova_Simulacao -> 704.34945
A86: 5 | C86: Quanto em 5 anos? | D86: =FV(Taxa_Nova_Simulacao,A86*12,Sugestao_Investimento*-1) -> 200999.57 | E86: =D86*Taxa_Nova_Simulacao -> 2166.7753
A87: 10 | C87: Quanto em 10 anos? | D87: =FV(Taxa_Nova_Simulacao,A87*12,Sugestao_Investimento*-1) -> 583466.18 | E87: =D87*Taxa_Nova_Simulacao -> 6289.7654
A88: 20 | C88: Quanto em 20 anos? | D88: =FV(Taxa_Nova_Simulacao,A88*12,Sugestao_Investimento*-1) -> 2696042.9 | E88: =D88*Taxa_Nova_Simulacao -> 29063.343
A89: 30 | C89: Quanto em 30 anos? | D89: =FV(Taxa_Nova_Simulacao,A89*12,Sugestao_Investimento*-1) -> 10345125 | E89: =D89*Taxa_Nova_Simulacao -> 111520.44
C93: Perfil | D93: Conservador
C94: VALOR A SER INVESTIDO POR MÊS | D94: =E76 -> 2400
...

Sheet Compra do carro
C14: Configurações
C15: Salário | E15: 8000
C16: Rendimento Carteira | E16: 0.0089
C17: Meta | E17: 80000
C18: Sugestão de Investimento (10% ao mês) | E18: =E15*10% -> 800
C21: INVESTIMENTO PARA COMPRAR UM CARRO
C22: Quanto investir por mês? | E22: =Valor_para_Carro -> 800
C23: Por quantos anos? | E23: 6
C24: Taxa de rendimento mensal? | E24: 0.01032
C25: Patrimônio acumulado? | E25: =FV(E24,Tempo_para_Carro*12,E22*-1) -> 84831.523
C26: Dividendos mensais? | E26: =Valor_Acumulado_Carro*Taxa_rendimento_Carro -> 875.46131
C29: Acompanhar Evolução | E29: Dividendo
A30: 1 | C30: Quanto em 1 anos? | D30: =FV(Taxa_rendimento_Carro,A30*12,$E$22*-1) -> 10164.083 | E30: =D30*Taxa_rendimento_Carro -> 104.89334
A31: 2 | C31: Quanto em 2 anos? | D31: =FV(Taxa_rendimento_Carro,A31*12,$E$22*-1) -> 21660.847 | E31: =D31*Taxa_rendimento_Carro -> 223.53994
A32: 3 | C32: Quanto em 3 anos? | D32: =FV(Taxa_rendimento_Carro,A32*12,$E$22*-1) -> 34665.028 | E32: =D32*Taxa_rendimento_Carro -> 357.74308
A33: 4 | C33: Quanto em 4 anos? | D33: =FV(Taxa_rendimento_Carro,A33*12,$E$22*-1) -> 49374.274 | E33: =D33*Taxa_rendimento_Carro -> 509.5425
A34: 5 | C34: Quanto em 5 anos? | D34: =FV(Taxa_rendimento_Carro,A34*12,$E$22*-1) -> 66012.147 | E34: =D34*Taxa_rendimento_Carro -> 681.24536
A35: 6 | C35: Quanto em 6 anos? | D35: =FV(Taxa_rendimento_Carro,A35*12,$E$22*-1) -> 84831.523 | E35: =D35*Taxa_rendimento_Carro -> 875.46131
C38: Perfil | D38: Moderado
C39: VALOR A SER INVESTIDO POR MÊS | D39: =Valor_para_Carro -> 800
C42: TIPO DE FII | D42: Percentual Sugerido | E42: Valores
C43: PAPEL | D43: =VLOOKUP($D$38&"-"&C43,'FIIs Para comprar Carro'!B:E,4,FALSE) -> 0.3 | E43: =D43*$D$39 -> 240
C44: TIJOLO | D44: =VLOOKUP($D$38&"-"&C44,'FIIs Para comprar Carro'!B:E,4,FALSE) -> 0.25 | E44: =D44*$D$39 -> 200
C45: HIBRIDOS | D45: =VLOOKUP($D$38&"-"&C45,'FIIs Para comprar Carro'!B:E,4,FALSE) -> 0.15 | E45: =D45*$D$39 -> 120
C46: FOFS | D46: =VLOOKUP($D$38&"-"&C46,'FIIs Para comprar Carro'!B:E,4,FALSE) -> 0.1 | E46: =D46*$D$39 -> 80
C47: DESENVOLVIMENTO | D47: =VLOOKUP($D$38&"-"&C47,'FIIs Para comprar Carro'!B:E,4,FALSE) -> 0.1 | E47: =D47*$D$39 -> 80
C48: HOTELARIAS | D48: =VLOOKUP($D$38&"-"&C48,'FIIs Para comprar Carro'!B:E,4,FALSE) -> 0.1 | E48: =D48*$D$39 -> 80
E49: =SUM(E43:E48) -> 800

Sheet Apoio
B3: CHAVE | C3: PERFIL | D3: TIPO DE FII | E3: %
B4: =C4&"-"&D4 -> Conservador-PAPEL | C4: Conservador | D4: PAPEL | E4: 0.3
B5: =C5&"-"&D5 -> Conservador-TIJOLO | C5: Conservador | D5: TIJOLO | E5: 0.5
B6: =C6&"-"&D6 -> Conservador-HIBRIDOS | C6: Conservador | D6: HIBRIDOS | E6: 0.1
B7: =C7&"-"&D7 -> Conservador-FOFS | C7: Conservador | D7: FOFS | E7: 0.05
B8: =C8&"-"&D8 -> Conservador-DESENVOLVIMENTO | C8: Conservador | D8: DESENVOLVIMENTO | E8: 0.05
B9: =C9&"-"&D9 -> Conservador-HOTELARIAS | C9: Conservador | D9: HOTELARIAS | E9: 0
B10: =C10&"-"&D10 -> Moderado-PAPEL | C10: Moderado | D10: PAPEL | E10: 0.22
B11: =C11&"-"&D11 -> Moderado-TIJOLO | C11: Moderado | D11: TIJOLO | E11: 0.35
B12: =C12&"-"&D12 -> Moderado-HIBRIDOS | C12: Moderado | D12: HIBRIDOS | E12: 0.18
B13: =C13&"-"&D13 -> Moderado-FOFS | C13: Moderado | D13: FOFS | E13: 0.05
B14: =C14&"-"&D14 -> Moderado-DESENVOLVIMENTO | C14: Moderado | D14: DESENVOLVIMENTO | E14: 0.1
B15: =C15&"-"&D15 -> Moderado-HOTELARIAS | C15: Moderado | D15: HOTELARIAS | E15: 0.1
... B21: =C21&"-"&D21 -> Agressivo-HOTELARIAS | C21: Agressivo | D21: HOTELARIAS | E21: 0.1

Sheet Sugestão de Investimento
B4: CHAVE | C4: PERFIL | D4: TIPO DE FII | E4: %
B5: =C5&"-"&D5 -> Conservador-PAPEL | C5: Conservador | D5: PAPEL | E5: 0.35
B6: =C6&"-"&D6 -> Conservador-TIJOLO | C6: Conservador | D6: TIJOLO | E6: 0.35
B7: =C7&"-"&D7 -> Conservador-HIBRIDOS | C7: Conservador | D7: HIBRIDOS | E7: 0.1
B8: =C8&"-"&D8 -> Conservador-FOFS | C8: Conservador | D8: FOFS | E8: 0.05
B9: =C9&"-"&D9 -> Conservador-DESENVOLVIMENTO | C9: Conservador | D9: DESENVOLVIMENTO | E9: 0.1
B10: =C10&"-"&D10 -> Conservador-HOTELARIAS | C10: Conservador | D10: HOTELARIAS | E10: 0.05
B11: =C11&"-"&D11 -> Moderado-PAPEL | C11: Moderado | D11: PAPEL | E11: 0.2
B12: =C12&"-"&D12 -> Moderado-TIJOLO | C12: Moderado | D12: TIJOLO | E12: 0.3
B13: =C13&"-"&D13 -> Moderado-HIBRIDOS | C13: Moderado | D13: HIBRIDOS | E13: 0.2
B14: =C14&"-"&D14 -> Moderado-FOFS | C14: Moderado | D14: FOFS | E14: 0.1
B15: =C15&"-"&D15 -> Moderado-DESENVOLVIMENTO | C15: Moderado | D15: DESENVOLVIMENTO | E15: 0.1
B16: =C16&"-"&D16 -> Moderado-HOTELARIAS | C16: Moderado | D16: HOTELARIAS | E16: 0.1
... B22: =C22&"-"&D22 -> Agressivo-HOTELARIAS | C22: Agressivo | D22: HOTELARIAS | E22: 0.15

Sheet FIIs Para comprar Carro
B3: CHAVE | C3: PERFIL | D3: TIPO DE FII | E3: %
B4: =C4&"-"&D4 -> Conservador-PAPEL | C4: Conservador | D4: PAPEL | E4: 0.25
B5: =C5&"-"&D5 -> Conservador-TIJOLO | C5: Conservador | D5: TIJOLO | E5: 0.45
B6: =C6&"-"&D6 -> Conservador-HIBRIDOS | C6: Conservador | D6: HIBRIDOS | E6: 0.1
B7: =C7&"-"&D7 -> Conservador-FOFS | C7: Conservador | D7: FOFS | E7: 0.05
B8: =C8&"-"&D8 -> Conservador-DESENVOLVIMENTO | C8: Conservador | D8: DESENVOLVIMENTO | E8: 0.1
B9: =C9&"-"&D9 -> Conservador-HOTELARIAS | C9: Conservador | D9: HOTELARIAS | E9: 0.05
B10: =C10&"-"&D10 -> Moderado-PAPEL | C10: Moderado | D10: PAPEL | E10: 0.3
B11: =C11&"-"&D11 -> Moderado-TIJOLO | C11: Moderado | D11: TIJOLO | E11: 0.25
B12: =C12&"-"&D12 -> Moderado-HIBRIDOS | C12: Moderado | D12: HIBRIDOS | E12: 0.15
B13: =C13&"-"&D13 -> Moderado-FOFS | C13: Moderado | D13: FOFS | E13: 0.1
B14: =C14&"-"&D14 -> Moderado-DESENVOLVIMENTO | C14: Moderado | D14: DESENVOLVIMENTO | E14: 0.1
B15: =C15&"-"&D15 -> Moderado-HOTELARIAS | C15: Moderado | D15: HOTELARIAS | E15: 0.1
... B21: =C21&"-"&D21 -> Agressivo-HOTELARIAS | C21: Agressivo | D21: HOTELARIAS | E21: 0.15
